Workbook

Sheet Nasıl Kullanılır
A1: MAKARYA · İÇERİK TABLOSU
A3: Bu dosya oyunun bütün içeriğinin ana kaynağıdır. Burada yapılan değişiklikler oyuna şöyle geçer:
A4: 1) Dosyayı düzenle ve kaydet (adını değiştirme: Makarya_Icerik.xlsx).
A5: 2) GitHub'da depoya yükle (Add file → Upload files) ya da Claude'a gönder.
A6: 3) Dosya oyunun formatına dönüştürülür ve birkaç dakika içinde oyunda görünür.
A8: ADLANDIRMA: ÖZELLİK = dokuz temel değer (Akıl, Çene, Kurnazlık, Cesaret, Pişkinlik, İtibar, Gönül, Dayanıklılık, Sosyal Radar). ROZET = zor işlerle kazanılan ödüller (Kitap Kurdu, Kantin Ekonomisti…).
A10: SAYFALAR
A11: Olaylar: Her satır bir olay. Olay ID benzersiz olmalı (küçük harf ve tire). Bölüm 1–10. Yaş örn. '12 yaş 6 ay'.
A12: Seçimler: Her satır bir seçim; Olay ID ile olaya bağlanır, Sıra ile dizilir. Bir olayda 2–5 seçim olur.
A13: • Kesin sonuçlu seçim: 'Kesin etki' (ör. İtibar +2, Çene +1) ve 'Kesin sonuç metni' doldurulur.
A14: • Zarlı seçim: Özellik + Zorluk + dört sonuç metni (Başarı, Kritik başarı, Başarısız, Kritik hata).
A15: • Mini oyunlu seçim: zarlı seçim + Mini oyun türü + başlık + ipucu + 'Yarım (mini oyun)' metni.
... A45: Aileler: Yalçın, Erdem, Keskin, Tan, Varlı, Şen

Sheet Özet
A1: Bölüm | B1: Olay sayısı | C1: Sabit olay | D1: Bir hayatta görülen | E1: Seçim sayısı | F1: Mini oyunlu seçim | G1: Ölüm riskli seçim
A2: 1 | B2: =COUNTIF(Olaylar!B:B,1) | C2: =COUNTIFS(Olaylar!B:B,1,Olaylar!I:I,"E") | D2: =VLOOKUP(1,Bölümler!A:C,3,FALSE) | E2: =SUMPRODUCT((COUNTIFS(Seçimler!A:A,Olaylar!A$2:A$486)>0)*(Olaylar!B$2:B$486=1)*COUNTIFS(Seçimler!A:A,Olaylar!A$2:A$486))
A3: 2 | B3: =COUNTIF(Olaylar!B:B,2) | C3: =COUNTIFS(Olaylar!B:B,2,Olaylar!I:I,"E") | D3: =VLOOKUP(2,Bölümler!A:C,3,FALSE) | E3: =SUMPRODUCT((COUNTIFS(Seçimler!A:A,Olaylar!A$2:A$486)>0)*(Olaylar!B$2:B$486=2)*COUNTIFS(Seçimler!A:A,Olaylar!A$2:A$486))
A4: 3 | B4: =COUNTIF(Olaylar!B:B,3) | C4: =COUNTIFS(Olaylar!B:B,3,Olaylar!I:I,"E") | D4: =VLOOKUP(3,Bölümler!A:C,3,FALSE) | E4: =SUMPRODUCT((COUNTIFS(Seçimler!A:A,Olaylar!A$2:A$486)>0)*(Olaylar!B$2:B$486=3)*COUNTIFS(Seçimler!A:A,Olaylar!A$2:A$486))
A5: 4 | B5: =COUNTIF(Olaylar!B:B,4) | C5: =COUNTIFS(Olaylar!B:B,4,Olaylar!I:I,"E") | D5: =VLOOKUP(4,Bölümler!A:C,3,FALSE) | E5: =SUMPRODUCT((COUNTIFS(Seçimler!A:A,Olaylar!A$2:A$486)>0)*(Olaylar!B$2:B$486=4)*COUNTIFS(Seçimler!A:A,Olaylar!A$2:A$486))
A6: 5 | B6: =COUNTIF(Olaylar!B:B,5) | C6: =COUNTIFS(Olaylar!B:B,5,Olaylar!I:I,"E") | D6: =VLOOKUP(5,Bölümler!A:C,3,FALSE) | E6: =SUMPRODUCT((COUNTIFS(Seçimler!A:A,Olaylar!A$2:A$486)>0)*(Olaylar!B$2:B$486=5)*COUNTIFS(Seçimler!A:A,Olaylar!A$2:A$486))
A7: 6 | B7: =COUNTIF(Olaylar!B:B,6) | C7: =COUNTIFS(Olaylar!B:B,6,Olaylar!I:I,"E") | D7: =VLOOKUP(6,Bölümler!A:C,3,FALSE) | E7: =SUMPRODUCT((COUNTIFS(Seçimler!A:A,Olaylar!A$2:A$486)>0)*(Olaylar!B$2:B$486=6)*COUNTIFS(Seçimler!A:A,Olaylar!A$2:A$486))
A8: 7 | B8: =COUNTIF(Olaylar!B:B,7) | C8: =COUNTIFS(Olaylar!B:B,7,Olaylar!I:I,"E") | D8: =VLOOKUP(7,Bölümler!A:C,3,FALSE) | E8: =SUMPRODUCT((COUNTIFS(Seçimler!A:A,Olaylar!A$2:A$486)>0)*(Olaylar!B$2:B$486=7)*COUNTIFS(Seçimler!A:A,Olaylar!A$2:A$486))
A9: 8 | B9: =COUNTIF(Olaylar!B:B,8) | C9: =COUNTIFS(Olaylar!B:B,8,Olaylar!I:I,"E") | D9: =VLOOKUP(8,Bölümler!A:C,3,FALSE) | E9: =SUMPRODUCT((COUNTIFS(Seçimler!A:A,Olaylar!A$2:A$486)>0)*(Olaylar!B$2:B$486=8)*COUNTIFS(Seçimler!A:A,Olaylar!A$2:A$486))
A10: 9 | B10: =COUNTIF(Olaylar!B:B,9) | C10: =COUNTIFS(Olaylar!B:B,9,Olaylar!I:I,"E") | D10: =VLOOKUP(9,Bölümler!A:C,3,FALSE) | E10: =SUMPRODUCT((COUNTIFS(Seçimler!A:A,Olaylar!A$2:A$486)>0)*(Olaylar!B$2:B$486=9)*COUNTIFS(Seçimler!A:A,Olaylar!A$2:A$486))
A11: 10 | B11: =COUNTIF(Olaylar!B:B,10) | C11: =COUNTIFS(Olaylar!B:B,10,Olaylar!I:I,"E") | D11: =VLOOKUP(10,Bölümler!A:C,3,FALSE) | E11: =SUMPRODUCT((COUNTIFS(Seçimler!A:A,Olaylar!A$2:A$486)>0)*(Olaylar!B$2:B$486=10)*COUNTIFS(Seçimler!A:A,Olaylar!A$2:A$486))
A12: Toplam | B12: =SUM(B2:B11) | C12: =SUM(C2:C11) | D12: =SUM(D2:D11) | E12: =SUM(E2:E11) | F12: =COUNTIF(Seçimler!M:M,"?*")-1 | G12: =COUNTIF(Seçimler!Y:Y,">0")

Sheet Olaylar
A1: Olay ID | B1: Bölüm | C1: Yaş | D1: Simge | E1: Başlık | F1: Olay metni | G1: Mekân | H1: Aile türü | I1: Sabit | J1: Ağırlık | K1: Gereken hafızalar | L1: Olmaması gereken hafızalar | M1: Gereken rozet | N1: Cinsiyet | O1: Sadece aileler | P1: Asgari özellik | Q1: Kavşak no | R1: Kavşak girişi | S1: Kazanırsan | T1: Kazanamazsan | U1: Herhangi biri hafıza | V1: Hat
A2: dogum | B2: 1 | C2: 0 yaş | D2: 👶 | E2: Ortam Fazla Aydınlık | F2: Makarya'ya yeni indin. Işıklar fazla parlak, oda fazla kalabalık. Herkes senden bir ses bekliyor; biri çoktan “Kime benziyor?” tartışmasını başlattı. | I2: E
A3: gece-vardiyasi | B3: 1 | C3: 3 ay | D3: 🌙 | E3: Gece Nöbeti | F3: Saat üç. Annen yarı uyuyor, baban yarı uyanık. Senin nöbetin daha yeni başlıyor. | H3: ev
A4: yabanci-krizi | B4: 1 | C4: 8 ay | D4: 🤓 | E4: Yabancı Krizi | F4: Tanımadığın bir teyze fazla hızlı, fazla gülerek geldi. Elleri yanaklarına uzanıyor: “Yerim seni!” Ciddi olup olmadığı belli değil.
A5: yasak-nesne | B5: 1 | C5: 10 ay | D5: 💎 | E5: Yasak Nesne | F5: Sehpada dokunmaman gereken parlak bir şey var: misafir gelince vitrinden inen kristal şekerlik. Bu bilgi şekerliği daha çekici yaptı. | H5: ev
A6: ilk-kelime | B6: 1 | C6: 1 yaş | D6: 💬 | E6: İlk Kelime | F6: Salon sessizleşti. Herkes ağzından çıkacak ilk anlamlı kelimeyi bekliyor. | H6: ev | I6: E
A7: ilk-adimlar | B7: 1 | C7: 15 ay | D7: 👣 | E7: İlk Adımlar | F7: Ayaktasın. Bu, teoride ilerleme sayılıyor.
A8: masadaki-telefon | B8: 1 | C8: 17 ay | D8: 📱 | E8: Masadaki Telefon | F8: Ekran parlıyor. Yetişkinler bu nesneye günün önemli bölümünü ayırıyor.
A9: dogum-gunu-pastasi | B9: 1 | C9: 19 ay | D9: 🎂 | E9: Doğum Günü Pastası | F9: Kuzeninin doğum günü. Masada bir pasta, bir mum ve seni ilgilendirmeyen bir sürü kural: önce şarkı, sonra mum, sonra dilim. Sen sadece pastayı gördün. | H9: sosyal
A10: vazo-kirildi | B10: 1 | C10: 2 yaş | D10: 🏺 | E10: Vazo Kırıldı | F10: Vazoyu kırdın. Parçalar yerde, sessizlik ağır. Kedi sana bakıyor. | H10: ev | I10: E
A11: ilk-harclik | B11: 1 | C11: 2 yaş 2 ay | D11: 🪙 | E11: İlk Harçlık | F11: Avucuna birkaç bozuk para bırakıldı. Deden “Kimseye verme” dedi. Annen “Ağzına atma” dedi. İki kural, bir avuç. | H11: para | J11: 2
A12: oyuncak-krizi | B12: 1 | C12: 2 yaş 4 ay | D12: 🧸 | E12: Oyuncak Krizi | F12: Kum havuzunda başka bir çocuk kovanı aldı. Onun annesi görmedi; seninki gördü ve “Paylaş” dedi. Yalnızsın. | H12: sosyal
A13: aile-toplantisi | B13: 1 | C13: 2 yaş 7 ay | D13: 🛋️ | E13: Büyükler Konuşuyor | F13: Salonda büyükler konuşuyor; çay ikinci demde, sesler alçak. Sana “Sen git oyna” dendi. Adın iki kez geçti. | H13: ev
A14: parkta-sira | B14: 1 | C14: 2 yaş 10 ay | D14: 🛝 | E14: Parkta Sıra | F14: Kaydırakta sıra var. Kural basit görünüyor. İnsanlar yüzünden değil.
A15: kim-yapti | B15: 1 | C15: 2 yaş 11 ay | D15: 🔍 | E15: Kim Yaptı? | F15: Salon duvarında keçeli kalemle çizilmiş kocaman bir güneş var. Altında imzaya benzeyen bir karalama. Baban elinde kalemin kapağıyla tek bir soru soruyor: “Kim yaptı?” | H15: ev | J15: 2
A16: kres-kapisi | B16: 1 | C16: 3 yaş | D16: 🏫 | E16: Kreş Kapısı | F16: Kapının arkasında başka çocuklar, katı kurallar ve paylaşılması gereken oyuncaklar var. | H16: okul-iş | I16: E
A17: ilk-arkadas | B17: 2 | C17: 3 yaş 1 ay | D17: 🤝 | E17: İlk Arkadaş | F17: Kreşin ilk haftası. Kum havuzunda senin boyunda bir çocuk var: elinde kürek, burnunda sümük, gözü sende. Öğretmen ikinizi yan yana oturttu: “Hadi bakalım, arkadaş olun.” Emirle arkadaş olunur mu, ikiniz de bilmiyorsunuz.
A18: oyuncagimi-aldi | B18: 2 | C18: 3 yaş 2 ay | D18: 😤 | E18: Oyuncağımı Aldı | F18: Kreşte bir çocuk elindeki arabayı aldı ve “Bu kreşin” dedi. Haklı. Ama araba senin elindeydi. | H18: sosyal
A19: ogretmen-yanlis-anladi | B19: 2 | C19: 3 yaş 4 ay | D19: 👩‍🏫 | E19: Öğretmen Seni Yanlış Anladı | F19: Öğretmen suyu senin döktüğünü sanıyor. Dökmedin; ama bardak senin önündeydi, elin de ıslak. Büyükler de yanılıyormuş. | H19: okul-iş
A20: parkin-buyuk-cocugu | B20: 2 | C20: 3 yaş 6 ay | D20: 🧗 | E20: Parkın Büyük Çocuğu | F20: Kaydırağın tepesinde koca bir çocuk oturuyor; yedi yaşında var, ön dişi yok. Ne kayıyor ne kimseyi çıkarıyor. Aşağıdan “Hadi ama!” diyen küçüklere tek bir cevabı var: “Burası benim.”
A21: market-kasasi | B21: 2 | C21: 3 yaş 8 ay | D21: 🍬 | E21: Market Kasası | F21: Kasa sırasındasın; şekerler tam senin göz hizana dizilmiş, annenin değil. Annen markete girmeden uyarmıştı: “Bugün şeker yok, anlaştık mı?” Anlaşmamıştınız; sen sadece başını sallamıştın. | H21: para
A22: baskasinin-dogum-gunu | B22: 2 | C22: 4 yaş | D22: 🎁 | E22: Başkasının Doğum Günü | F22: Alt kattaki çocuğun doğum günü. Pasta onun, balonlar onun, hediyeler onun. Annen kapıda son kez fısıldadı: “Hediyeleri o açacak, sen değil.” | H22: sosyal
A23: en-guzel-oyuncak | B23: 2 | C23: 4 yaş 1 ay | D23: 🤖 | E23: En Güzel Oyuncak | F23: Kuzeninin odasında, rafın en üstünde kocaman, parlak kırmızı bir itfaiye arabası duruyor. Halan kapıdan uyardı: “O yeni, dokunmayın.” Odadaki dört çocuk o andan beri yalnızca ona bakıyor.
A24: ilk-gercek-yalan | B24: 2 | C24: 4 yaş 2 ay | D24: 🤥 | E24: İlk Gerçek Yalan | F24: Buzdolabındaki misafir pastasının bir köşesi eksik; tam çikolatalı köşesi. Annen pastaya baktı, sonra senin dudağının kenarına: “Bunu kim yedi?” Bu kez ne yaptığını biliyorsun. Annen de biliyor gibi bakıyor. | H24: ev
A25: mahalle-bakkali | B25: 2 | C25: 4 yaş 4 ay | D25: 🏪 | E25: Mahalle Bakkalı | F25: Liste elinde, para cebinde. Bakkal apartmanın altında; annen balkondan izliyor. Bakkal her şeyi biliyor gibi bakıyor; annen de. | H25: para
A26: kaybolan-bozuk-para | B26: 2 | C26: 4 yaş 5 ay | D26: 🔎 | E26: Kaybolan Bozuk Para | F26: Parkta, ayağının dibinde parlak bir bozuk para var. Sahibi görünmüyor. Annen de görünmüyor; bankta komşu teyzeyle termostan üçüncü çayı içiyor. | H26: para
A27: takim-seciliyor | B27: 3 | C27: 7 yaş | D27: ⚽ | E27: Takım Seçiliyor | F27: Teneffüste maç. İki kaptan karşılıklı ayak ayak yürüyor; ayağı üste gelen ilk seçecek. Sen kale direği yapılan çantaların yanında bekliyorsun.
A28: sana-guluyorlar | B28: 2 | C28: 4 yaş 9 ay | D28: 😅 | E28: Sana Gülüyorlar | F28: Kreşte öğretmen sordu: “Büyüyünce ne olacaksın?” “Kedi” dedin; bütün gün uyuyor, kimse kızmıyor. Üç çocuk kahkahayı bastı. Neyin komik olduğunu hâlâ anlamadın. | H28: sosyal
A29: ilk-kucuk-sir | B29: 2 | C29: 5 yaş | D29: 🤫 | E29: İlk Küçük Sır | F29: Sıra arkadaşın kulağına eğildi, eliyle ağzını kapattı: “Benim dedemin dişleri çıkıyor. Geceleri bardağa koyuyor.” Sonra ekledi: “Kimseye söyleme.” Hayatında duyduğun en büyük sır bu. | H29: sosyal
A30: aileler-kiyasliyor | B30: 2 | C30: 5 yaş 2 ay | D30: 📏 | E30: Aileler Kıyaslıyor | F30: Komşu teyze çaya geldi, oğlunu da getirdi. Çaylar gelmeden başladı: “Bizimki okumayı söktü.” Annen elindeki şekerliği bıraktı: “Bizimki de alfabeyi tersten söylüyor.” Bu senin için de haberdi. | H30: okul-iş
A31: kirilan-oyuncak | B31: 2 | C31: 5 yaş 4 ay | D31: 🔧 | E31: Kırılan Oyuncak | F31: Babanın bayramda aldığı konuşan robotun kolu elinde kaldı. Kırmak istememiştin; kolu bir tur daha çevirmiştin, o kadar. Robot son kez “Merhaba dostum!” dedi ve sustu.
A32: mahalle-turnuvasi | B32: 2 | C32: 5 yaş 5 ay | D32: 🏃 | E32: Mahalle Turnuvası | F32: Sokakta yarış var: apartmanın kapısından bakkalın önüne kadar. Kurallar her dakika değişiyor; en büyük çocuk ne derse o. Bakkal sandalyesini kapıya çekti; bitiş çizgisi artık o. | J32: 2
A33: harclik-pazarligi | B33: 2 | C33: 5 yaş 7 ay | D33: 💰 | E33: İlk Harçlık Pazarlığı | F33: Pazar akşamı. Baban cüzdanını açtı: “Bundan sonra her hafta harçlığın var.” Avucuna iki bozukluk koydu. Sen bozukluklara baktın, sonra cüzdana; cüzdanda daha çok vardı. | H33: para
A34: okul-hazirligi | B34: 2 | C34: 5 yaş 9 ay | D34: 🎒 | E34: Okul Hazırlığı | F34: Çanta, harfler, defterler. Annen önlüğü üçüncü kez ütüledi; okula daha koca bir kış var. | H34: okul-iş | J34: 2
A35: tepsiyle-kayak | B35: 2 | C35: 5 yaş 10 ay | D35: 🛷 | E35: Tepsiyle Kayak | F35: Kar yağdı. Mahallenin en dik yokuşu trafiğe kapandı. Çocuklar mutfaklardan tepsi kaçırıyor.
A36: ilkokul-kapisi | B36: 2 | C36: 6 yaş | D36: 🏫 | E36: İlkokul Kapısı | F36: Büyük bina, küçük sıralar, bir sürü kural. Üstünde yepyeni bir önlük, yakanda annenin iğneyle taktığı nazar boncuğu. Kapıda ağlayan veliler var; ağlayanlar sizinkiler. | H36: okul-iş | I36: E
A37: ilk-ders | B37: 3 | C37: 6 yaş 1 ay | D37: ✏️ | E37: İlk Ders | F37: Okulun ilk günü. Annen hâlâ camın arkasından el sallıyor; öğretmen perdeyi çekti ve sordu: “Kim okumayı biliyor?” Yirmi sekiz çocuğun yarısı el kaldırdı, yarısı perdeye baktı. | H37: okul-iş | I37: E
A38: sira-arkadasi | B38: 3 | C38: 6 yaş 2 ay | D38: 🪑 | E38: Sıra Arkadaşı | F38: Yanına oturan çocuk kalemlerini sayıyor. Senin kalemlerini de. | H38: sosyal
A39: teneffus-kantini | B39: 3 | C39: 6 yaş 4 ay | D39: 🥪 | E39: Kantin Kuyruğu | F39: Teneffüs on dakika, kantin kuyruğu on iki dakika. Kantinci tek başına: bir elinde tost makinesinin kapağı, öbüründe para üstü. Öndeki üçüncü sınıflar seni görmüyor bile. | H39: para | I39: E
A40: odev-nerede | B40: 3 | C40: 6 yaş 7 ay | D40: 📚 | E40: Ödev Nerede? | F40: Sabah 07.40, servis kapıda korna çalıyor. Ödev defteri ne çantada ne masada. Annen bir yandan saçını tarıyor, bir yandan soruyor: “Yaptın, değil mi?” | H40: ev
...

Sheet Seçimler
A1: Olay ID | B1: Sıra | C1: Seçim metni | D1: Özellik | E1: Zorluk | F1: Kesin etki | G1: Kesin sonuç metni | H1: Başarı | I1: Kritik başarı | J1: Başarısız | K1: Kritik hata | L1: Yarım (mini oyun) | M1: Mini oyun | N1: Mini oyun başlığı | O1: Mini oyun ipucu | P1: Mini oyun ayarı | Q1: Gereken rozet | R1: Gereken hafıza | S1: İç ses açar | T1: Kazandırdığı rozet | U1: Seçince hafıza | V1: Başarıda hafıza | W1: Kritik hatada hafıza | X1: Silinen hafıza | Y1: Ölüm riski % | Z1: Ölüm sebebi | AA1: Aile desteği | AB1: Başarısızlıkta hafıza | AC1: Gereken varlık | AD1: Kazanç kademesi | AE1: Gereken aile desteği | AF1: Varlık kaybı | AG1: Engelleyen hafıza | AH1: Gereken özellik değeri | AI1: Lakap | AJ1: Cinsiyet
A2: dogum | B2: 1 | C2: Ağla | F2: Çene +1 | G2: Ağladın. Odadaki herkes rahat bir nefes aldı; babaannen “Ciğeri sağlammış” dedi. Hayattaki ilk övgünü aldın.
A3: dogum | B3: 2 | C3: Daha çok ağla | D3: Çene | E3: Orta | H3: Sesini biraz daha açtın. Hemşire koştu, baban ayağa fırladı. İlk dersin: bu evde sesi yükselten kazanıyor. | I3: Doğumhanedeki herkes aynı anda sustu, sonra hepsi sana koştu. İlk günden masada söz hakkın var. | J3: Daha çok ağladın ama yandaki bebek senden yüksek sesliydi. İlk gün, ilk rekabet. | K3: O kadar ağladın ki hıçkırık tuttu, sabaha kadar geçmedi. Babaannen “Nazar” dedi, annen “Açtır” dedi, doktor “Normal” dedi. Baban hepsini videoya çekti; video hâlâ aile grubunda. | T3: Ses Yükseltince Oluyor | AI3: Hıçkırık
A4: dogum | B4: 3 | C4: Etrafı izle | D4: Sosyal Radar | E4: Orta | H4: Konuşmadan önce ortamı okumayı seçtin. | I4: Odadaki altı kişiyi tek tek süzdün. Hemşire seni “müfettiş” diye çağırmaya başladı. | J4: Etrafı izledin ama ışıklar fazla parlaktı. Gördüğün tek şey tavandı. | K4: İzlemeye öyle daldın ki doktor seni bir saat gözleme aldı. Bütün aile camın önüne dizildi. Dünyadaki ilk saatin vitrinde geçti. | T4: Sessiz Gözlemci
A5: dogum | B5: 4 | C5: Sessiz kal | F5: Sosyal Radar +1 | G5: Sessiz kaldın. Önce doktor, sonra annen, sonra babaannen eğilip yüzüne baktı. Üçü de “Bir şey mi var?” dedi. Yoktu; sadece bakıyordun.
A6: gece-vardiyasi | B6: 1 | C6: Kendi kendine uyu | D6: Dayanıklılık | E6: Zor | H6: İki saat deliksiz uyudun. Annen de uyudu, baban da. Sabah ikisi de aynı şeyi söyledi: “Ne güzel bir geceydi.” İki saat. | I6: Sabaha kadar deliksiz uyudun. Annenle baban ise uyuyamadı; “Bu kadar sessiz olmaz” diye saatlerce başında nöbet tuttular. | J6: Gözlerini kapadın, açtın, kapadın. Uyku gelmedi; onun yerine babaannen geldi, “Gaz sancısı” dedi, karnını ovdu. | K6: Kendi kendine uyumaya çalışırken kendi kendini uyandırdın. Bu sinirle sabaha kadar daha çok ağladın. | L6: Yarım saat uyudun. Ev halkı bunu tam bir gece gibi kutladı. | M6: simon | N6: Ninni Sırası | O6: Sırayı dinle, aynı sırayla tekrar et. | P6: {"items": ["🌙", "🧸", "🍼", "🎵"]}
A7: gece-vardiyasi | B7: 2 | C7: Ağlayarak yardım çağır | D7: Çene | E7: Kolay | H7: Ağladın; annen geldi. Yarı uykuda, tek gözü kapalı, kolları açık. Ama geldi. | I7: Tek bir “ıngaa” ile bütün ev ayaklandı: annen biberonla, baban bezle, babaannen nazar boncuğuyla geldi. Üç çözüm, bir bebek. Hepsini kabul ettin. | J7: Ağladın; kapının ardından “Uyur şimdi” dendi. Uyumadın. Onlar uyudu. | K7: Ağladın, ev halkı seferber oldu. Annen, baban ve babaannen aynı anda “Ben bakarım” diye kapıya yüklendi; üçü birden kapıda sıkıştı. Yardım çağırdın, şimdi yardıma yardım lazım.
A8: gece-vardiyasi | B8: 3 | C8: Sessizce bekle | F8: Sosyal Radar +1 | G8: Sessizce tavana baktın. Sabah annen “Hiç ağlamadı” dedi; babaannen “Hasta mı?” diye alnına dokundu.
A9: yabanci-krizi | B9: 1 | C9: Anneni ara | D9: Sosyal Radar | E9: Kolay | H9: Anneni buldun, yüzünü omzuna gömdün. Teyze “Utangaçmış” dedi. Değildin; seçiciydin. | I9: Anneni tek bakışta buldun; yabancı, hiç yaklaşmamış gibi geri çekildi. | J9: Anneni aradın. Bulduğun kişi halanmış. | K9: Anne diye kucağına atladığın kişi yabancının ta kendisiydi.
A10: yabanci-krizi | B10: 2 | C10: Gözlüğüne saldır | D10: Cesaret | E10: Orta | H10: Bir hamlede gözlüğü kaptın. Teyze bir süre annene “Neredesin?” diye seslendi; annen yanındaydı. | I10: Gözlük elinde. Teyze ne olduğunu anlayana kadar sen çoktan zaferini ilan ettin. | J10: Teyze senden hızlı çıktı; gözlüğü cebine koydu, yanağını bir kez daha sıktı. | K10: Gözlüğe uzandın, küpesini yakaladın. Teyze çığlık attı, sen ağladın, annen bir saat özür diledi. Teyze bir daha gelmedi; küpenin öbür teki de. | L10: Parmakların çerçeveye değdi ama gözlük sende kalmadı. | M10: timing | N10: Gözlüğü Kap! | O10: Kırmızı işareti yeşil alanda durdur.
A11: yabanci-krizi | B11: 3 | C11: Kabullen | F11: Sosyal Radar +1 | G11: Kabullendin. İki yanağın da sıkıldı, kucaktan kucağa bir tur attın. Akşam yanakların hâlâ kırmızıydı; teyze çok memnun gitti.
A12: yabanci-krizi | B12: 4 | C12: Ağla | F12: Çene +1 | G12: Ağladın. Teyze “Ay, beni sevmedi” deyip geri çekildi ve annene küstü. Annen bunu bayrama kadar duyacak.
A13: yasak-nesne | B13: 1 | C13: Dokunma | F13: İtibar +1 | G13: Dokunmadın. Annen “Aferin” dedi ve şekerliği yine de vitrine kaldırdı. Güven var ama sınırlı.
A14: yasak-nesne | B14: 2 | C14: Anne çıkana kadar bekle | D14: Kurnazlık | E14: Kolay | H14: Annen telefona döndüğü an şekerliği okşadın: soğuk, kaygan, güzel. Annen döndüğünde elin dizindeydi. | I14: Anne çıktı, sen aldın, anne döndü, nesne yerindeydi. Kimse hiçbir şey anlamadı. | J14: Beklerken uyuyakaldın. Uyandığında şekerlik vitrine dönmüştü. | K14: Annen çıkmadı; kapı aralığından izledi. Elin şekerliğe değdiği an “Gördüm!” dedi. Şekerlik vitrine, sen oyun parkına kaldırıldın.
A15: yasak-nesne | B15: 3 | C15: Direkt al | D15: Pişkinlik | E15: Kolay | H15: Aldın. Annen “Bırak” dedi; bırakmadın. Misafir “Aman, çocuk işte” dedi. Misafir sayesinde bir dakika senindi. | I15: Aldın ve kimse itiraz edemedi. Yüz ifaden tüm soruları cevapladı. | J15: Uzandın; şekerlik sehpanın ortasındaydı, kolun kenarında kaldı. | K15: Aldın, düşürdün, kırdın. Babaannenin çeyizinden kalan şekerlikmiş. O akşam misafire şeker tabakta geldi; herkes nedenini biliyordu.
A16: ilk-kelime | B16: 1 | C16: Anne | F16: Gönül +1 | G16: “Anne” dedin. Annen ağladı. Baban “Ben de buradayım” dedi; kimse duymadı.
A17: ilk-kelime | B17: 2 | C17: Baba | F17: Çene +1 | G17: “Baba” dedin. Baban o akşam bütün sülaleyi aradı. Annen “Dokuz ay ben taşıdım” diye mırıldandı.
A18: ilk-kelime | B18: 3 | C18: Mama | F18: Dayanıklılık +1 | G18: “Mama” dedin. Önce herkes güldü, sonra herkes mutfağa koştu. Bu kelime hâlâ işe yarıyor.
A19: ilk-kelime | B19: 4 | C19: Para | D19: Kurnazlık | E19: Zor | H19: “Para” dedin. Salon sustu. Deden gülmeye başladı; annen “Kimden duydu bunu?” diye babana baktı. | I19: “Para” dedin ve elini uzattın. Deden cüzdanını çıkardı. Aile bunu hâlâ konuşuyor. | J19: “Para” dedin ama televizyon açıktı, kimse duymadı. Yine de sen ne dediğini biliyorsun. | K19: “Para” dedin. Babaannen üç gün boyunca seni “küçük tefeci” diye çağırdı. | T19: Kumbara Çocuğu | V19: ilkKelimePara | AI19: Küçük Tefeci
A20: ilk-adimlar | B20: 1 | C20: Koşmayı dene | D20: Cesaret | E20: Orta | H20: Yürümeden önce hızlanmayı tercih ettin. Adımlar sallantılı ama gerçek. | I20: İki ayağın da yerde, rüzgâr arkanda. Bir anlığına evren dengede. | J20: Denge seni henüz ikna etmedi. | K20: Bir adım attın. Yer senden daha hızlı davrandı. | L20: Bir adım, sonra güvenli bir oturuş. | M20: timing | N20: Dengede Kal | O20: İbre yeşil alandayken DURDUR'a bas. Art arda tutturdukça kombo kazanırsın.
A21: ilk-adimlar | B21: 2 | C21: Mobilyaya tutun | D21: Dayanıklılık | E21: Çok Kolay | H21: Koltuğa tutundun, sehpaya geçtin, sehpada durdun. Üstündeki çay bardakları tıkırdadı; annen koştu, sen gülümsedin. | I21: Koltuktan sehpaya, sehpadan kapıya: evin bütün tutunacak yerlerini bir turda gezdin. Baban “Bu çocuk yürüdü sayılır” dedi. | J21: Tuttuğun mobilya tekerlekliymiş. | K21: Tuttuğun şey masa örtüsüydü. Üstündekilerle birlikte indin.
A22: ilk-adimlar | B22: 3 | C22: Önce diğerlerini izle | D22: Akıl | E22: Kolay | H22: Babanı izledin: önce bir ayak, sonra öbürü. Denedin: iki adım, bir koltuk. Baban “Benden öğrendi” dedi; doğruydu. | I22: Kediyi izledin: dört ayak daha dengeli, iki ayak daha prestijli. Prestij kazandı. | J22: İzledin, izledin. O sırada herkes oturuyordu. | K22: Örnek aldığın kişi dedendi. Bir adım, bir “of”, bir bel tutma. Yürümeyi değil “of”u öğrendin; bir hafta her kalkışta “of” dedin.
A23: masadaki-telefon | B23: 1 | C23: Dokunma | F23: İtibar +1 | G23: Dokunmadın. Annen “Bak, bizimki telefona bakmıyor” dedi; komşuya, telefondan.
A24: masadaki-telefon | B24: 2 | C24: Ekranı kurcala | D24: Kurnazlık | E24: Kolay | H24: Ekranı açtın, her yere bastın. Telefonun dili değişti; baban üç gün Öte Diyar diliyle idare etti. | I24: Ekranı açtın ve babanın çalma listesini 'Ninniler' olarak güncelledin. | J24: Ekran kilitliydi. Sen de bir süre kilitlendin. | K24: Rastgele dokunuşların babanın patronunu görüntülü aradı. Patron açtı. Ekranda sen, arkada atletle koşturan baban.
A25: masadaki-telefon | B25: 3 | C25: Gizlice al | D25: Kurnazlık | E25: Zor | H25: Telefonu aldın; kilidi açamadın ama kamerayı açtın. Kırk üç fotoğraf: tavan, burun, tavan. | I25: Telefonu aldın, bir oyun açtın, rekor kırdın. Kimse şifreyi nasıl bildiğini anlamadı. | J25: Telefon elinde titreşti; irkildin, bıraktın. Halıda titremeye devam etti, sen de. | K25: Telefonu aldın ve doğrudan su bardağına bıraktın. Pirinç torbası devreye girdi. | T25: Şifreyi Bilen
A26: dogum-gunu-pastasi | B26: 1 | C26: Bekle | D26: Dayanıklılık | E26: Kolay | H26: Pasta hâlâ orada. Sen de hâlâ buradasın. | I26: Sabrın ödüllendirildi: en büyük dilim, üstünde çilekle sana geldi. | J26: Bekledin, bekledin; sıra sana geldiğinde kremalı kısım bitmişti. | K26: Bekledin, bekledin, uyuyakaldın. Uyandığında pasta bitmişti; sana mum kaldı. Fotoğraflarda herkes yiyor, sen uyuyorsun.
A27: dogum-gunu-pastasi | B27: 2 | C27: Pastaya erken saldır | D27: Pişkinlik | E27: Orta | H27: Şarkı bitmeden parmağını kremaya daldırdın. Teyzen “Dur!” dedi; parmak çoktan ağzındaydı. | I27: Pastanın en güzel köşesi artık senin. Herkes alkışladı, çünkü başka seçenek yoktu. | J27: Uzandın, biri tabağı kaydırdı. Elin havayı kremaladı. | K27: Pastaya daldın. Pasta da sana daldı. Aile albümüne kalıcı kayıt. | AI27: Kremalı
A28: dogum-gunu-pastasi | B28: 3 | C28: Mumları önce üfle | D28: Pişkinlik | E28: Orta | H28: Doğum günü sahibinin kim olduğu geçici olarak belirsizleşti. | I28: Mumları söndürdün, dilek tuttun, alkışları topladın. Hediyeler de yön değiştirmek üzere. | J28: Üfledin ama mumlar senden daha kararlıydı. | K28: Üfledin; mum yerine pastanın süsü uçtu. Doğum günü çocuğu ağlamaya başladı. | L28: Mumların yarısı söndü, yarısı direndi. Kuzenin kalanları üfledi; alkış ikinize bölündü. | M28: timing | N28: Mumu Üfle | O28: İbre yeşil alandayken DURDUR'a bas. Art arda tutturdukça kombo kazanırsın. | T28: Sahne Sever
A29: vazo-kirildi | B29: 1 | C29: Bekle | F29: İtibar +2 | G29: Parçaların yanında bekledin. Annen geldi; önce ellerine baktı, sonra vazoya. “Elini kestin mi?” Kesmemiştin. Vazo ikinci sıradaydı.
A30: vazo-kirildi | B30: 2 | C30: Kaç | D30: Kurnazlık | E30: Orta | H30: Kaçtın, yatağına girdin, uyuyormuş gibi yaptın. Annen geldi, baktı, inanmadı; ama kanıt da bulamadı. | I30: Kaçtın ve üç dakika sonra 'Ne oldu?' diye içeri girdin. Annen bile inandı; babaannen 'Bu çocuk oyuncu olur' dedi. | J30: Kaçarken terlikler ses yaptı. Şüpheli tespit edildi. | K30: Kaçarken ikinci vazoyu da devirdin. O da babaannenindi; babaannen bu akşam yemeğe geliyor.
A31: vazo-kirildi | B31: 3 | C31: Kediyi suçla | D31: Pişkinlik | E31: Çok Zor | H31: Savunma yaratıcıydı. Kedinin odada olmaması küçük bir ayrıntıydı. | I31: Kedi mahkûm edildi. Mama tayınları kısıldı. Sen o gece iki tatlı yedin. | J31: Kediye baktın. Kedi sana baktı. Ailen ikinize de baktı. Kimse ikna olmadı. | K31: Kediyi suçladın. Kedi o sırada annenin kucağındaydı. | U31: kediSuclu | AI31: Kedinin Savcısı
A32: vazo-kirildi | B32: 4 | C32: Ayak seslerini say, tam zamanında ağla | D32: Çene | E32: Kolay | H32: Ağladın. Annen seni kucağına aldı, sırtını sıvazladı; vazoyu ancak sen susunca hatırladı. | I32: Ağladın; anne vazoyu değil seni sordu. Vazo resmî kayıtlara 'kaza' olarak geçti. | J32: Ağladın; anne önce vazoya baktı. Sonra sana. Sonra yine vazoya. | K32: Ağladın ama kediyle aynı anda. Anne ikinizi de şüpheli ilan etti. | S32: Sosyal Radar
A33: vazo-kirildi | B33: 5 | C33: Parçaları sakla | D33: Kurnazlık | E33: Orta | H33: Parçaları koltuğun altına ittin. Annen vazoyu üç gün sonra aradı. Üç gün, şüpheli listesinden düşmeye yetti. | I33: Parçalar göz açıp kapayıncaya kadar kayboldu. Vazo hiç var olmamış gibi. | J33: Parçalar senden hızlı yayıldı. | K33: Parçaları toplarken daha fazla ses çıkardın. Ev halkı toplandı. | L33: Çoğunu sakladın ama bir parça hâlâ şüpheli biçimde ortada. | M33: collect | N33: Delilleri Topla | O33: Parçalar fark edilmeden önce hepsine dokun. | P33: {"piece": "🧩"}
A34: ilk-harclik | B34: 1 | C34: Annene ver | F34: İtibar +1 | G34: Paraları annene uzattın. “Benim akıllı evladım” dedi, cebine koydu. Para bir daha görünmedi; “akıllı evlat” kaldı.
A35: ilk-harclik | B35: 2 | C35: Oyuncak iste | F35: Çene +1 | G35: Parayı uzatıp “Oyuncak” dedin. Para yetmedi, farkı deden ödedi. Oyuncak iki gün dayandı; deden hâlâ hatırlatıyor.
A36: ilk-harclik | B36: 3 | C36: Parayı sakla | D36: Kurnazlık | E36: Zor | H36: Paraları yastığının altına sakladın. Annen çarşaf değiştirirken buldu, geri koydu, hiçbir şey demedi. İkiniz de biliyorsunuz. | I36: Parayı sakladın, bir hafta sonra unuttuğun bir sürpriz olarak buldun. Faiz kavramına ilk adım. | J36: Sakladığın yeri unuttun. Para artık evin ortak mirası. | K36: Parayı çorabının içine sakladın. Akşam çorap çamaşıra gitti. Para makinede; sesi hâlâ geliyor. | T36: Yastık Altı Ekonomisti
A37: ilk-harclik | B37: 4 | C37: Bir çocukla takas yap | D37: Çene | E37: Zor | H37: İki bozukluk verdin, bir oyuncak araba aldın. Kuzeninin annesi “O arabayı biz almıştık” dedi. Anlaşma geçerli, teyze küs. | I37: İki bozuk parayı bir oyuncak arabaya çevirdin, sonra arabayı üç bozuk paraya. Kârdasın. | J37: Parayı uzattın. Çocuk baktı, krakerini yedi, gitti. | K37: Takas ettin: bütün bozukluklar gitti, eline ısırılmış yarım bir kraker geçti. Öbür çocuk annesine “Kazandım” dedi. Haklıydı. | T37: Küçük Tüccar
A38: ilk-harclik | B38: 5 | C38: Faiz sor | D38: Kurnazlık | E38: Kolay | H38: Parayı dedene geri uzattın: “Daha.” Deden güldü, bir bozukluk daha koydu. Ailede faiz ilk kez böyle konuşuldu. | I38: “Daha” dedin, deden verdi. “Daha” dedin, babaannen verdi. Avucun dolduğunda halan “Bu çocuk bizi bitirecek” dedi. | J38: “Daha” dedin. Kimse paradan bahsettiğini anlamadı; eline bir bisküvi tutuşturdular. | K38: “Daha” dedin, elini uzattın. Babaannen paranın hepsini aldı: “Çocuk açgözlü olmasın.” Para gitti, bisküvi de gelmedi. | R38: ilkKelimePara
A39: oyuncak-krizi | B39: 1 | C39: Paylaş | D39: Gönül | E39: Zor | H39: Kovayı ona bıraktın. Ağlamadın. Annen bunu akşam babana üç kez anlattı. | I39: Kovayı bıraktın, küreği de uzattın. Birlikte kule yaptınız. İki anne yan yana oturdu; yıllar sürecek bir komşuluk kum havuzunda başladı. | J39: Paylaşmayı denedin. Elin bırakmadı. İki yaşında el, kafadan hızlıdır. | K39: Paylaştın. Çocuk kovayı kumla doldurdu ve kafana boşalttı. Saçından bir hafta kum döküldü.
A40: oyuncak-krizi | B40: 2 | C40: Başka oyuncak teklif et | D40: Çene | E40: Kolay | H40: “Bunu al, kovamı ver” dedin. Düşündü, kabul etti. İkiniz de kazandığınızı sanıyorsunuz. | I40: Eski oyuncağını teklif ettin, yenisini geri aldın, karşı taraf sana teşekkür bile etti. Tarihe 'başarılı takas' olarak geçti. | J40: Teklif ettin. Baktı, burnunu kırıştırdı, kovayla oynamaya devam etti. | K40: Teklif ettiğin oyuncağı da aldı. Şimdi resmen iki oyuncak açığın var.
...

Sheet İç Sesler
A1: Olay ID | B1: Özellik | C1: Zorluk | D1: İç ses metni | E1: Başarısızlık metni | F1: Seçenek açar
A2: dogum | B2: Sosyal Radar | C2: Kolay | D2: Odada altı kişi var. Beşi sana bakıyor. Altıncısı faturaya.
A3: dogum | B3: Pişkinlik | C3: Orta | D3: Sahne senin. Işıklar hazır. Ağlamak, açılış için yeterince güçlü bir numara.
A4: yasak-nesne | B4: Kurnazlık | C4: Kolay | D4: Parlak şeyler pahalıdır. Pahalı şeyler yüksekte durur. Bu sehpada bir hesap hatası var.
A5: yasak-nesne | B5: İtibar | C5: Orta | D5: Bu nesneye dokunursan birileri üzülecek. Muhtemelen sen, biraz sonra.
A6: vazo-kirildi | B6: Sosyal Radar | C6: Orta | D6: Kedi seni izlemiyor. Annenin ayak seslerini izliyor. Dört saniyen var. | F6: E
A7: vazo-kirildi | B7: Pişkinlik | C7: Zor | D7: Kedinin avukatı yok. Sadece söylüyorum.
A8: vazo-kirildi | B8: İtibar | C8: Kolay | D8: Bu vazo babaanneden kalmaydı. Babaanne hâlâ hayatta. Bu durumu daha da kötüleştiriyor. | E8: …İtibarın bu sırada başka bir şeyle meşguldü.
A9: ilk-harclik | B9: Kurnazlık | C9: Orta | D9: Bu bozukluklar tek başına bir şey değil. Ama dedenin cebi her bayram dolu. Bayram çok.
A10: ilk-harclik | B10: Çene | C10: Kolay | D10: Karşıdaki çocuğun elinde kraker var. Kraker de bir para birimidir.
A11: kim-yapti | B11: İtibar | C11: Kolay | D11: Doğruyu söylersen bugün kötü geçer. Yalan söylersen bu gece kötü geçer.
A12: kim-yapti | B12: Akıl | C12: Orta | D12: Baban kalemin kapağını tutuyor. Kalemin kendisi senin cebinde. Bu bir soruşturma değil, bir sadakat testi. | F12: E
A13: ilk-gercek-yalan | B13: Pişkinlik | C13: Orta | D13: Göz teması kur. Gözünü kırpma. Kırpma dedik.
A14: ilk-gercek-yalan | B14: İtibar | C14: Kolay | D14: Annen sana hâlâ “benim akıllım” diyor. Bu cümlenin bugün bir sınavı var.
A15: mahalle-bakkali | B15: Sosyal Radar | C15: Orta | D15: Bakkal mahalledeki herkesin borcunu ezbere biliyor. Seninkini de. Henüz yok ama biliyor.
A16: mahalle-bakkali | B16: Kurnazlık | C16: Zor | D16: Terazinin kefesinin altında bir sakız yapışık. Yıllardır orada. Terazi yıllardır bir sakız ağırlığında yanılıyor.
A17: sana-guluyorlar | B17: Dayanıklılık | C17: Kolay | D17: Bu an geçecek. Otuz yıl sonra bir düğünde biri hatırlatacak. O an da geçecek.
A18: sana-guluyorlar | B18: Cesaret | C18: Orta | D18: Gülen üç kişi. İkisi neye güldüğünü bilmiyor. Üçüncüsü de emin değil.
A19: aileler-kiyasliyor | B19: Sosyal Radar | C19: Orta | D19: Teyzenin ağzı “Ne tatlı” diyor. Gözleri “Ama bizimki kadar değil” diyor.
A20: tepsiyle-kayak | B20: Akıl | C20: Orta | D20: Yokuşun sonunda bir çöp konteyneri var. Tepsinin freni yok. Bu iki bilgiyi aynı cümlede düşün.
A21: tepsiyle-kayak | B21: Cesaret | C21: Kolay | D21: Asker gibi otur, tepsiyi sıkı tut, gözünü kapama. Annen balkonda değilken, marş!
A22: ilkokul-kapisi | B22: Cesaret | C22: Kolay | D22: Bina büyük ama kapı normal boyutta. Başlangıç için yeterli.
A23: ilkokul-kapisi | B23: Akıl | C23: Orta | D23: Koridorda on iki kapı var. Resimli olanlar küçük sınıflar. Sen artık küçük sınıfsın. Bunu kabullen.
A24: sinif-baskani | B24: Çene | C24: Orta | D24: Vaat ne kadar büyükse oy o kadar çok. Uygulama kısmı seçimden sonraki bir sorun.
... A26: balkondaki-ucurtma | B26: Cesaret | C26: Kolay | D26: Dut dalı sağlamdır evladım, biz de çıkardık. Bir kere ben de düştüm, bayram ziyaretine alçıyla gittim. Güzel günlerdi.
A27: balkondaki-ucurtma | B27: İtibar | C27: Orta | D27: Bu uçurtmayı sana deden aldı. Pazar günü gelip “Uçurtma nerede?” diye soracak. | E27: …İtibarın sesini rüzgâra kaptırdı.
A28: veli-toplantisi | B28: Sosyal Radar | C28: Zor | D28: Öğretmenin önündeki defter kalın. İnce defter iyi haberdir. Kalın defterin sonunda annen “Eve gidince konuşuruz” der.
A29: veli-toplantisi | B29: Dayanıklılık | C29: Kolay | D29: Kapının bu tarafında olmak, ömrünün en uzun yirmi dakikası olacak. Şimdilik.
A30: karne-gunu | B30: Dayanıklılık | C30: Orta | D30: Eve 800 metre var. Her adım bir savunma cümlesi. Yeterince yürüdün, yeterince yazdın.
A31: karne-gunu | B31: Akıl | C31: Kolay | D31: Karnedeki notlar değişmeyecek. Değişecek tek şey, onları nasıl sunduğun. Bu da bir tür matematik.
A32: b4-ilk-telefon | B32: Kurnazlık | C32: Orta | D32: Denetim şifresi babanın doğum yılı. Bütün şifreler gibi. | F32: E
A33: b4-ilk-telefon | B33: İtibar | C33: Kolay | D33: Bu telefonun faturası annenin adına. Her bildirim bir gün onun ekranına da düşecek.
A34: b4-aile-grubu | B34: Sosyal Radar | C34: Orta | D34: Halanın 'Herkes görüyor ama kimse yazmıyor' mesajı sana. Henüz bilmiyorsun.
A35: b4-aile-grubu | B35: Pişkinlik | C35: Zor | D35: Bu grup bir sahne. Seyirci yaşlı ama sadık.
A36: b4-oyun-faturasi | B36: Akıl | C36: Orta | D36: Bir elmas paketi, bir haftalık market alışverişi. Oyun bunu söylemiyor. Ekstre söyleyecek.
A37: b4-oyun-faturasi | B37: Kurnazlık | C37: Zor | D37: Ödeme, annenin parmak iziyle onaylanıyor. Annen şu an kanepede, akşam dizisinin karşısında uyukluyor. | F37: E
A38: b4-flut | B38: İtibar | C38: Kolay | D38: Flüt, bir ailenin sabrını ölçmek için icat edildi. Bu, bilimsel değil ama doğru.
A39: b4-sinif-grubu | B39: Sosyal Radar | C39: Orta | D39: Grupta öğretmenin kızı da var. Kimse bunu hatırlamıyor. | F39: E
A40: b4-sinif-grubu | B40: İtibar | C40: Kolay | D40: Yazdığın her şey birinin ekran görüntüsü klasörüne gidecek. Oradan hiçbir şey çıkmaz.
A41: b4-kisa-video | B41: Pişkinlik | C41: Orta | D41: Kamera açılınca utanç kapanır. Bu bir teknik özellik.
...

Sheet Geçmişten
A1: Olay ID | B1: Hafıza | C1: Geçmişten metni
A2: ilk-harclik | B2: ilkKelimePara | C2: İlk kelimen 'Para' olduğundan beri bu konuda seni ciddiye alıyorlar.
A3: kim-yapti | B3: kediSuclu | C3: Vazo olayından beri ev halkı kedinin ifadelerine daha az, seninkilere daha çok dikkat ediyor.
A4: ilk-gercek-yalan | B4: kediSuclu | C4: Annen bir an kediye baktı, sonra vazgeçti. Vazodan beri bu evde kediye kimse inanmıyor.
A5: ilk-gercek-yalan | B5: yalanci | C5: Duvardaki güneşten beri bu evde “Kim yaptı?” sorulunca herkes önce senin ellerine bakıyor. Bugün ellerin temiz; dudağın değil.
A6: kirilan-oyuncak | B6: kediSuclu | C6: Bu evde bir şey kırılınca artık önce sana bakıyorlar. Kedi aklandı.
A7: harclik-pazarligi | B7: ilkKelimePara | C7: İlk kelimesi 'Para' olan birinden beklenen an nihayet geldi.
A8: ilkokul-kapisi | B8: yapiskan | C8: Kreş kapısındaki bacak olayı ailede hâlâ anlatılıyor.
A9: sira-arkadasi | B9: sirVerdi | C9: Kreşteki sır hikâyesi okula senden önce gelmiş. Yeni sıra arkadaşın biraz temkinli.
A10: odev-nerede | B10: kediSuclu | C10: Bu evde suç hep kediye atılır. Kedi bunu biliyor; bu sabah ödev defterinin yanına bile yaklaşmıyor.
A11: bayram-harcligi | B11: ilkKelimePara | C11: Akrabalar zarfı uzatırken 'Hani ilk kelimesi para olan' diye gülüştü.
A12: mahalle-maci | B12: cesurPark | C12: Parktaki büyük çocuk karşı takımda. Seni tanıdı, selam verdi.
... A421: b10-tek-fincan | B421: ask-evliligi | C421: Elli yıl önce sana tuzlu bir kahve getirmişti. Bu sabah kahveni kendin tuzladın; içemedin.

Sheet Rozetler
A1: Rozet | B1: Açıklama | C1: Bonus | D1: Otomatik özellik
A2: Hayat Arşivcisi | B2: Kimin neyi, ne zaman, hangi bayramda söylediğini tarih ve saatiyle hatırlarsın. | C2: Akıl +1, Sosyal Radar +1
A3: Balkon Müfettişi | B3: Sokakta olan hiçbir şey kayda geçmeden sonuçlanmaz. | C3: Sosyal Radar +2
A4: Son Sözü Söyler | B4: Masadaki her tartışma sende kapanır. Kimse itiraz edecek enerjiyi bulamaz. | C4: Çene +1, Pişkinlik +1
A5: Ekran Yerlisi | B5: Her uygulamanın ayarlar menüsünü ailenden iyi bilirsin. Ailen de bunu bilir, ama hangi ayarı bilmez. | C5: Kurnazlık +1, Sosyal Radar +1
A6: Grup Diplomatı | B6: Mesaj grubunda bir şey yazmadan önce üç kez okursun. Dördüncüde silersin. | C6: Sosyal Radar +1, Çene +1
A7: Kantin Ekonomisti | B7: Tostla ayran arasındaki kâr marjını ezbere bilirsin. | C7: Kurnazlık +1, Çene +1
A8: Grup Yöneticisi | B8: Mesaj gruplarını kurar, yönetir, gerektiğinde sessize alırsın. | C8: Sosyal Radar +1, Çene +1
A9: Deneme Kurdu | B9: Yüzlerce deneme sınavından sonra sınav salonu sana ikinci evin gibi gelir. | C9: Akıl +1, Dayanıklılık +1
A10: Kestirme Bilir | B10: Şehrin bütün arka sokaklarını, otopark geçişlerini ve açık kalan kapılarını bilirsin. | C10: Kurnazlık +1, Dayanıklılık +1
A11: Bütçe Tablocusu | B11: Her harcamanın bir hücresi var. Hücrelerin çoğu kırmızı. | C11: Akıl +1, Kurnazlık +1
A12: Nöbet Disiplini | B12: Saat üçte uyanık kalmayı bilirsin. Kimse sana nedenini sormaz. | C12: Dayanıklılık +2
A13: Selamı Var | B13: Birileri senin hakkında iyi şeyler söylüyor. Bazıları seni gerçekten tanıyor. | C13: Çene +1, Sosyal Radar +1
... A45: Kilit Kırıcı | B45: Her sistemin bir açığı vardır. | C45: Akıl +2
A46: Ukala Ama Haklı | B46: Sorunu parçalarına ayırırsın; parçaları da herkese tek tek anlatırsın. | C46: Akıl +2 | D46: Akıl
A47: Sözünü Geçirir | B47: Söylediğin şey genelde olur. | C47: Çene +2 | D47: Çene
A48: Açık Bulur | B48: Kurallardaki boşlukları fark edersin. | C48: Kurnazlık +2 | D48: Kurnazlık
A49: Geri Adım Atmaz | B49: Korkuyu hissedersin ama yine de yaparsın. | C49: Cesaret +2 | D49: Cesaret
A50: Yüzü Kızarmaz | B50: Utanma duygusu seni yavaşlatmaz. | C50: Pişkinlik +2 | D50: Pişkinlik
A51: Sözü Senet | B51: Mahallede sözün senet yerine geçer; kefil aranınca adın ilk sırada. | C51: İtibar +2 | D51: İtibar
A52: Kolay Dağılmaz | B52: Baskı altında toparlanırsın. | C52: Dayanıklılık +2 | D52: Dayanıklılık
A53: Odayı Okur | B53: Kimin ne hissettiğini herkesten önce anlarsın. | C53: Sosyal Radar +2 | D53: Sosyal Radar
A54: Kitap Kurdu | B54: Köşedekilerden kaçıp kütüphaneye sığındı; sınav salonları ona yabancı değil. | C54: Akıl +2
A55: Tezgâh Ağzı | B55: Müşteri daha ağzını açmadan ne alacağını, ne kadar pazarlık edeceğini ve kimin selamıyla geldiğini bilirsin. | C55: Çene +2
A56: İki Dilli Rüya | B56: İki dilde düşünür, iki dilde küfreder, iki dilde de yanlış anlaşılırsın. | C56: Sosyal Radar +1, Akıl +1
A57: Kalbi Geniş | B57: Sevdiğini söylemekten çekinmezsin; sofrada herkes senin yanına oturmak ister. | C57: Gönül +2 | D57: Gönül

Sheet Hafıza
A1: Hafıza | B1: Final kartı etiketi | C1: Sonraki bölümde | D1: Bölüm sonu cümlesi
A2: kediSuclu | B2: Vazo davasında kediyi suçladı. | D2: “İki yaşında kediyi mahkûm ettirdi.”
A3: ilkKelimePara | B3: İlk kelimesi 'Para' oldu. | D3: “İlk kelimesi ‘para’ oldu; deden cüzdanını o gün çıkardı.”
A4: yalanci | B4: Küçükken “Kim yaptı?” sorusuna yalan söyledi. | D4: “Ne kırılsa, ne eksilse ‘Ben değilim’ derdi; dudağının kenarında çikolata olsa bile.”
A5: sirVerdi | B5: Kreşte bir arkadaşının sırrını yaydı. | D5: “Arkadaşının dedesinin dişleri bardakta uyuyormuş; akşama bütün kreş biliyordu.”
A6: cesurPark | B6: Parktaki büyük çocuğa kafa tuttu. | D6: “Üç buçuk yaşında parktaki koca çocuğa ‘Burası herkesin!’ dedi; titreyerek ama dedi.”
A7: yapiskan | B7: Kreş kapısında bacağa sarıldı. | D7: “Kreş kapısında bacak bırakmadı; bizde de öyleydi.”
A8: baskan | B8: Sınıf başkanı seçildi. | D8: “Sınıf başkanı oldu; evde de seçim yaptırdı.”
A9: kediGeldi | B9: Eve bir de yavru kedi getirtti. | D9: “Bir kedi yetmedi, yavrusunu da getirtti; ikisine de ben bakıyorum.”
A10: camKirildi | B10: Komşunun camıyla tanıştı. | D10: “Komşunun camını kırdı; cam değişti, komşu değişmedi.”
A11: tepsiTekeli | B11: Bir kış boyunca mahallenin bütün kayak tepsileri onun balkonunda toplandı. | D11: “Bir kış mahallenin bütün tepsileri onun balkonundaydı; annesi çayı tabakla taşıdı.”
A12: alcili-kol | B12: Çocukluğunda bir kolu alçıda geçti. | D12: “Kolu alçıya girdi; alçıyı bütün mahalle imzaladı, ben de.”
A13: vasiyet-yazildi | B13: Vasiyetini noterde, iki şahit önünde imzaladı. | D13: “Vasiyeti noterde, üç nüsha; kimin neyi alacağı belli, kimin kime küseceği değil.”
... A17: kitaplasti | B17: Hayat hikâyesi bir torun ve bir yapay zekâ tarafından kitaplaştırıldı. | D17: “Hayatı kitap oldu; bayramda bütün akrabaya birer tane dağıttık.”
A18: iyi-lise | B18: Lise sınavından iyi bir liseye yerleşti. | C18: İyi bir lisede dört yıl: yüksek beklentiler, erken başlayan dershane ve Büyük Sınav'da bir adım önde başlamak. | D18: “Sınavı kazandı; mahallede üç gün baklava dağıttık.”
A19: lakapli | B19: Ortaokulda takılan lakap, lise mezuniyetine kadar görevde kaldı. | D19: “Ortaokulda taktıkları ad liseye kadar gitti.”
A20: sokak-yasagi | B20: Mahallede bir sokaktan bir daha hiç geçemedi; okul yolu ömür boyu dört dakika uzun kaldı. | D20: “O sokaktan bir daha geçmedi; okul yolu dört dakika uzadı, hâlâ da nedenini anlatmaz.”
A21: ilk-mesaj | B21: İlk hoşlantısına ilk mesajı gönderdi. 'Selam.'
A22: oyun-faturasi | B22: Oyun içi alışverişle ailenin kart ekstresini tarihe geçirdi. | D22: “Annesinin parmağıyla ejderha aldı; o ay sofrada et görmedik.”
A23: dershaneli | B23: Ergenliğinin cumartesilerini dershanede geçirdi. | D23: “Her cumartesi dershaneye gitti; çantasına böreği ben koydum.”
A24: yz-odevci | B24: Ödevlerini yapay zekâya yaptırmayı denedi; öğretmen 'ayrıca'ları saydı.
A25: kendi-odasi | B25: On üç yaşında kendi odasını resmî başvuruyla aldı.
A26: fuar-birincisi | B26: Okul bilim fuarında yanardağ yapmadan birinci oldu. | D26: “Yanardağ yapmadan birinci oldu; jüri hâlâ nasıl olduğunu soruyor.”
A27: takim-oyuncusu | B27: Okul takımının seçmelerini geçti; forma büyük geldi. | D27: “Forma ona büyük geldi; sonra forma küçüldü, o büyüdü.”
A28: yanlis-grup | B28: Aile grubuna yanlış mesaj gönderdi; evin yemek listesi o günden beri tartışmalı. | D28: “Annesinin yemeğini yanlışlıkla aile grubuna şikâyet etti; o yemek bir daha pişmedi.”
A29: universiteli | B29: Büyük Makarya Sınavı'nı geçip üniversiteye girdi. | D29: “Sınavı kazandı; aile grubunda üç gün tebrik bitmedi, ben herkese ayrı ayrı teşekkür ettim.”
A30: ilk-sevgili | B30: Lisede bir parkta, bir bankta, bir karış mesafeyi kapattı. | C30: Bir sevgilin var. Yetişkinliğe ilk kez iki kişi giriyorsun. | D30: “Parkta bir bankta el ele tutuşmuşlar; karşı apartmandaki komşu bana herkesten önce haber verdi.”
A31: ilk-ayrilik | B31: İlk ayrılığını bir mesajlaşma uygulamasında, üç noktanın gölgesinde yaşadı. | D31: “İlk ayrılığında odasına kapandı, üç gün aynı şarkıyı dinledi; ben kapının önüne çay bıraktım.”
A32: ai-kopyaci | B32: Tarih ödevini bir yapay zekâya emanet etti.
A33: okul-temsilcisi | B33: Okul temsilcisi seçildi; ikinci tost makinesi vaadiyle.
A34: doktor-sozu | B34: Bir akşam yemeğinde aileye doktor olacağına söz verdi. | D34: “Bir akşam yemeğinde doktor olacağına söz verdi; babaannesi ertesi sabah bütün mahalleye duyurdu.”
A35: yurt-disi-hayali | B35: Öte Diyar'daki bir okuldan cevap alacak kadar ileri gitti.
A36: ehliyetli | B36: Ehliyetini aldı; arabanın anahtarını almak ayrı bir hikâyeydi.
A37: yurtdisi-gordu | B37: Bir dönem Öte Diyar'da düzgün peynir aradı.
A38: usta-eli | B38: Bir ustanın elinden meslek kaptı.
A39: depozito-yandi | B39: Bir kiralık evden depozitosunu hiç geri alamadı.
A40: universitesiz | B40: Üniversite yerine doğrudan hayata atıldı.
A41: taki-defteri | B41: Düğün takılarını kuruşu kuruşuna deftere geçirdi; defter hâlâ güncelleniyor.
A42: arabali | B42: Araba sahibi oldu; muayene tarihini doğum gününden iyi bilir.
A43: site-yoneticisi | B43: Site toplantısında itiraz ederken yönetici seçildi. | D43: “Apartmana yönetici oldu; gece üçte kapısı çalınıyor, o yine de seviniyor.”
...

Sheet Ölüm Sebepleri
A1: Asgari yaş | B1: Azami yaş | C1: Mezar taşı metni | D1: Gereken hafıza | E1: Mekân grubu
A2: 18 | B2: 40 | C2: Kira sözleşmesinin ek maddelerini okurken. Madde 14 hâlâ açıklığa kavuşmadı. | E2: ev
A3: 18 | B3: 40 | C3: Kargo takip ekranında 'dağıtıma çıktı' yazısını beklerken. Kargo ertesi gün teslim edildi. | E3: ev
A4: 18 | B4: 40 | C4: Ev arkadaşıyla bulaşık nöbeti tartışmasının dördüncü turunda. Bulaşıklar hâlâ lavaboda. | E4: ev
A5: 18 | B5: 40 | C5: Staj başvurusunun on yedinci formunu doldururken. Başvuru alındı. | E5: is
A6: 18 | B6: 40 | C6: Yeni işinin ilk gününde, asansörde kimseyle göz teması kurmamaya çalışırken. | E6: is
A7: 18 | B7: 40 | C7: Kısa video uygulaması için aynı dansın kırk birinci çekiminde. Kırkıncısı zaten yüklenmişti. | D7: fenomen | E7: ev
A8: 18 | B8: 40 | C8: Sabah koşusunun son turunda, saatin adım sayısını kontrol ederken. Hedef tamamlanmıştı. | D8: sporcu | E8: yol
A9: 18 | B9: 40 | C9: Taksit planını yeniden yapılandırmak için bankayı ararken. Sıradaki müşteri temsilcisi hâlâ hatta. | D9: borclu | E9: ev
A10: 40 | B10: 60 | C10: Site yönetimine itiraz dilekçesini teslim ederken. Dilekçe hâlâ değerlendiriliyor. | E10: ev
A11: 40 | B11: 60 | C11: Kombi tamircisini beklerken. Tamirci ertesi gün geldi. | E11: ev
A12: 40 | B12: 60 | C12: Performans değerlendirme toplantısında 'beklentileri karşılıyor' ifadesini duyduğu anda. | D12: meslek-beyazyaka | E12: is
A13: 40 | B13: 60 | C13: Dükkânın kepengini indirirken, günün son müşterisinin 'Bir şey soracaktım' demesiyle. | D13: meslek-esnaf | E13: is
A14: 40 | B14: 60 | C14: Mesai bitimine üç dakika kala gelen evrakı imzalarken. Evrak işleme alındı. | D14: meslek-memur | E14: is
A15: 40 | B15: 60 | C15: Müşteriden gelen 'Ufak bir revizyon' mesajını açarken. Revizyon hâlâ sürüyor. | D15: meslek-serbest | E15: is
A16: 40 | B16: 60 | C16: Veli toplantısında söz alma sırası kendisine geldiği anda. | D16: cocuklu | E16: kurum
A17: 40 | B17: 60 | C17: Aile grubundaki uzun bir sesli mesajı ikinci kez dinlerken. | E17: ev
A18: 40 | B18: 60 | C18: Evlilik yıldönümü hediyesini son dakikada paketlerken. Kurdele bağlandı. | D18: evli | E18: ev
A19: 40 | B19: 60 | C19: Bir sigarayı daha son sigara ilan ederken. Bu sefer gerçekten son oldu. | D19: sigara | E19: ev
A20: 60 | B20: 75 | C20: Emeklilik dilekçesinin onayını beklerken. Onay ertesi hafta geldi. | E20: kurum
A21: 60 | B21: 75 | C21: Emekli ikramiyesiyle aldığı motosikletle ilk virajda. Viraj kazandı. | D21: emekli | E21: yol
A22: 60 | B22: 75 | C22: Pazarın kapanışında son kasa domatesi pazarlık ederken. Domatesler yarı fiyatına alındı. | E22: yol
A23: 60 | B23: 75 | C23: Torunuyla saklambaç oynarken, en iyi saklanma yerini bulduğu anda. Oyunu kazandı. | D23: torunlu | E23: ev
A24: 60 | B24: 75 | C24: Apartman toplantısında asansör bakım ücretinin paylaştırılmasını oylarken. | E24: ev
A25: 60 | B25: 75 | C25: Mahalle kahvesinde, bir tavla partisinin son zarında. Zar çift geldi. | E25: sosyal
A26: 60 | B26: 75 | C26: Bahçede domates fidesine konuşurken. Fide büyümeye devam etti. | E26: ev
A27: 60 | B27: 75 | C27: Kedisinin mamasını son indirimli paketten alırken. Kedi durumu kabullenmedi. | D27: kediGeldi | E27: yol
A28: 60 | B28: 75 | C28: Eski takipçilerinden birinin 'Siz ölmediniz mi?' yorumuna cevap yazarken. Cevap gönderilmedi. | D28: fenomen | E28: ev
A29: 60 | B29: 75 | C29: Sabah yürüyüşünde, ilk kez kimsenin geçemediği yokuşu geçtiği anda. Yokuş belediyeye bildirildi. | D29: sporcu | E29: yol
A30: 75 | B30: 90 | C30: Uykusunda, huzur içinde. Alarmı kurmayı unutmamıştı. | E30: ev
A31: 75 | B31: 90 | C31: Öğleden sonra şekerlemesinde, huzur içinde. Şekerleme uzadı. | E31: ev
A32: 75 | B32: 90 | C32: Balkonda, sokağın akşam raporunu tamamladıktan sonra. Rapor eksiksizdi. | E32: ev
A33: 75 | B33: 90 | C33: Uykusunda, huzur içinde. Yanındaki kedi uyanmadı. | D33: kediGeldi | E33: ev
A34: 75 | B34: 90 | C34: Emekli maaşını çekip bayram zarflarını hazırlarken. Zarflar dağıtıldı. | D34: emekli | E34: is
A35: 75 | B35: 90 | C35: Torunlarına aynı hikâyeyi yedinci kez anlatırken. Sonunu bu sefer herkes birlikte söyledi. | D35: torunlu | E35: ev
A36: 75 | B36: 90 | C36: Eşiyle akşam çayında, bardaklar tam tazelendiği anda. Çay soğumadı. | D36: evli | E36: ev
A37: 75 | B37: 90 | C37: Koltukta, kumanda elinde, huzur içinde. Dizinin sonunu sonraki bölüm açıkladı. | E37: ev
A38: 75 | B38: 90 | C38: Eski iş arkadaşlarının yıllık buluşmasında, kendi eski masasına oturduğu anda. | D38: meslek-memur | E38: sosyal
A39: 75 | B39: 90 | C39: Pazar kahvaltısında, bütün ailesi masadayken. Yumurta tam kıvamındaydı. | D39: cocuklu | E39: ev
A40: 90 | B40: 110 | C40: Uykusunda, huzur içinde. Sabahın ilk çayı demlenmişti. | E40: ev
...

Sheet Bölümler
A1: Bölüm | B1: Ad | C1: Seçilecek olay | D1: Beklenen özellik | E1: Yaş aralığı | F1: Son görsel (olay ID) | G1: Son yaş | H1: Son metin | I1: Sonraki düğme
A2: 1 | B2: Ev | C2: 6 | D2: 25 | E2: Doğum → 3 yaş | F2: kres-kapisi | G2: 3 YAŞ | H2: Ev güvenliydi. Şimdi başka çocuklar var. | I2: BÖLÜM II · DIŞ DÜNYA
A3: 2 | B3: Dış Dünya | C3: 6 | D3: 29 | E3: 3 → 6 yaş | F3: ilkokul-kapisi | G3: 6 YAŞ | H3: Artık yalnızca aileyi değil, dış dünyanın kurallarını da okumaya başladın. | I3: BÖLÜM III · OKUL YILLARI
A4: 3 | B4: Okul Yılları | C4: 6 | D4: 32 | E4: 6 → 9 yaş | F4: karne-gunu | G4: 9 YAŞ | H4: Karne elinde, karakter ortada. | I4: BÖLÜM IV · ERGENLİK
A5: 4 | B5: Ergenlik | C5: 7 | D5: 34 | E5: 10 → 14 yaş | F5: b4-lise-sinavi | G5: 14 YAŞ | H5: Sesin çatladı, telefonun çatlamadı. Önceliklerin belli. | I5: BÖLÜM V · SINAV ÇAĞI
A6: 5 | B6: Sınav Çağı | C6: 8 | D6: 37 | E6: 15 → 18 yaş | F6: b5-mezuniyet | G6: 18 YAŞ | H6: Resmen yetişkinsin. Sistem bunu kutlamak için sana ilk faturanı hazırlıyor. | I6: BÖLÜM VI · GENÇ YETİŞKİN
A7: 6 | B7: Genç Yetişkin | C7: 8 | D7: 38 | E7: 18 → 26 yaş | F7: b6-meslek-secimi | G7: 26 YAŞ | H7: Bir yolun, bir adresin ve bir kredi kartı ekstren var. Hayat seni artık ciddiye alıyor. | I7: BÖLÜM VII · KARİYER VE AİLE
A8: 7 | B8: Kariyer ve Aile | C8: 8 | D8: 40 | E8: 26 → 40 yaş | F8: b7-evlilik-karari | G8: 40 YAŞ | H8: Kırk yaşına bastın. Ayakkabın da bastı; o da artık yorgun. | I8: BÖLÜM VIII · ORTA YAŞ
A9: 8 | B9: Orta Yaş | C9: 6 | D9: 40 | E9: 40 → 55 yaş | F9: b8-lise-bulusmasi | G9: 55 YAŞ | H9: Gözlüğün yakın için, sabrın uzak için. İkisi de reçeteli. | I9: BÖLÜM IX · OLGUNLUK
A10: 9 | B10: Olgunluk | C10: 6 | D10: 42 | E10: 55 → 70 yaş | F10: b9-emeklilik | G10: 70 YAŞ | H10: Yetmiş yaşındasın. Zamanın bol, randevuların dolu; hangisinin daha önemli olduğuna sen karar veriyorsun. | I10: BÖLÜM X · SON PERDE
A11: 10 | B11: Son Perde | C11: 5 | D11: 43 | E11: 70 yaş ve sonrası | F11: son-soz
